<?xml version='1.0'?>

<robot name="right_arm" xmlns:xacro="http://www.ros.org/wiki/xacro">

<xacro:include filename="$(find human_arm_description)/urdf/right_arm.gazebo" />
<!-- <xacro:property name="prefix" value="right_"/> -->

<link name="${prefix}shoulder">
    <inertial>
      <origin xyz="0 0 0" rpy="0 0 0" />
      <mass value="0.0363799" />
          <inertia ixx="0.003" ixy="0" ixz="0" iyy="0.0030" iyz="0" izz="0.0035"/>
    </inertial>
    <visual>
      <origin xyz="0 0 0" rpy="0 0 0" />
      <geometry>
        <mesh  filename="package://human_arm_description/meshes/shoulder.stl" />
      </geometry>
      <material name="">
        <color rgba="0.79216 0.81961 0.93333 1" />
      </material>
    </visual>
    <collision>
      <origin xyz="0 0 0" rpy="0 0 0" />
      <geometry>
         <mesh  filename="package://human_arm_description/meshes/shoulder.stl" />
      </geometry>
    </collision>
</link>

<joint
    name="${prefix}shoulder_humerus" type="revolute">
    <origin xyz="0 0 0.015" rpy="0 0 0" />
    <parent link="${prefix}shoulder" />
    <child link="${prefix}humerus" />
    <axis xyz="1 0 0" />
    <limit lower="-3.14" upper="0.345" effort="150.0" velocity="1"/>
    <!-- dynamics damping="5" friction="0.0"/ -->
</joint>


<link name="${prefix}humerus">
    <inertial>
      <origin xyz="0 0 0" rpy="0 0 0" />
      <mass value="0.7" />
          <inertia ixx="0.003" ixy="0" ixz="0" iyy="0.0030" iyz="0" izz="0.0035"/>
    </inertial>
    <visual>
      <origin xyz="0 0 0" rpy="0 0 0" />
      <geometry>
        <mesh  filename="package://human_arm_description/meshes/humerus.stl" />
      </geometry>
      <material name="">
        <color rgba="0.79216 0.81961 0.93333 1" />
      </material>
    </visual>
    <collision>
      <origin xyz="0 0 0" rpy="0 0 0" />
      <geometry>
          <mesh  filename="package://human_arm_description/meshes/humerus.stl" />
      </geometry>
    </collision>
</link>



<joint
    name="${prefix}humerus_elbow" type="revolute">
    <origin xyz="-0.001 -0.15 0.0147" rpy="0 0 0" />
    <parent link="${prefix}humerus" />
    <child link="${prefix}elbow" />
    <axis xyz="0 1 0" />
    <limit lower="-3.142" upper="0" effort="150.0" velocity="1"/>
    <!-- dynamics damping="5" friction="0.0"/ -->
</joint>



<link name="${prefix}elbow">
    <inertial>
      <origin xyz="0.00116385 -0.0740893 -0.0073153" rpy="-1.21278e-13 1.94289e-16 -0.0115373" />
      <mass value="0.7" />
          <inertia ixx="0.003" ixy="0" ixz="0" iyy="0.0030" iyz="0" izz="0.0035"/>
    </inertial>
    <visual>
      <origin xyz="0 0 0" rpy="0 0 0" />
      <geometry>
        <mesh  filename="package://human_arm_description/meshes/elbow.stl" />
      </geometry>
      <material name="">
        <color rgba="0.79216 0.81961 0.93333 1" />
      </material>
    </visual>
    <collision>
      <origin xyz="0 0 0" rpy="0 0 0" />
      <geometry>
          <mesh  filename="package://human_arm_description/meshes/elbow.stl" />
      </geometry>
    </collision>
</link>





<joint
    name="${prefix}elbow_forearm" type="revolute">
    <origin xyz="0.01 -0.145 -0.015" rpy="0 0 0" />
    <parent link="${prefix}elbow" />
    <child link="${prefix}forearm" />
    <axis xyz="0 0 1" />
    <limit lower="0" upper="2.4" effort="150.0" velocity="1"/>
    <!-- dynamics damping="5" friction="0.0"/ -->
</joint>



<link name="${prefix}forearm">
    <inertial>
      <origin xyz="0.00116385 -0.0740893 -0.0073153" rpy="-1.21278e-13 1.94289e-16 -0.0115373" />
      <mass value="0.7" />
          <inertia ixx="0.003" ixy="0" ixz="0" iyy="0.0030" iyz="0" izz="0.0035"/>
    </inertial>
    <visual>
      <origin xyz="0 0 0" rpy="0 0 0" />
      <geometry>
        <mesh  filename="package://human_arm_description/meshes/forearm.stl" />
      </geometry>
      <material name="">
        <color rgba="0.79216 0.81961 0.93333 1" />
      </material>
    </visual>
    <collision>
      <origin xyz="0 0 0" rpy="0 0 0" />
      <geometry>
          <mesh  filename="package://human_arm_description/meshes/forearm.stl" />
      </geometry>
    </collision>
</link>




<joint
    name="${prefix}forearm_wristy" type="revolute">
    <origin xyz="0.000 -0.185 0.015" rpy="0 0 0" />
    <parent link="${prefix}forearm" />
    <child link="${prefix}wristy" />
    <axis xyz="0 1 0" />
    <limit lower="-3.142" upper="2" effort="150.0" velocity="1"/>
    <!-- dynamics damping="5" friction="0.0"/ -->
</joint>



<link name="${prefix}wristy">
    <inertial>
      <origin xyz="0 0 0" rpy="0 0 0" />
      <mass value="0.7" />
          <inertia ixx="0.003" ixy="0" ixz="0" iyy="0.0030" iyz="0" izz="0.0035"/>
    </inertial>
    <visual>
      <origin xyz="0 0 0" rpy="0 0 0" />
      <geometry>
        <mesh  filename="package://human_arm_description/meshes/wristy.stl" />
      </geometry>
      <material name="">
        <color rgba="0.79216 0.81961 0.93333 1" />
      </material>
    </visual>
    <collision>
      <origin xyz="0 0 0" rpy="0 0 0" />
      <geometry>
          <mesh  filename="package://human_arm_description/meshes/wristy.stl" />
      </geometry>
    </collision>
</link>






<joint
    name="${prefix}wristy_wristx" type="revolute">
    <origin xyz="0.000 -0.06 0.002" rpy="0 0 0" />
    <parent link="${prefix}wristy" />
    <child link="${prefix}wristx" />
    <axis xyz="0 0 1" />
    <limit lower="-0.697" upper="0.697" effort="150.0" velocity="1"/>
    <!-- dynamics damping="5" friction="0.0"/ -->
</joint>



<link name="${prefix}wristx">
    <inertial>
      <origin xyz="0 0 0" rpy="0 0 0" />
      <mass value="0.7" />
          <inertia ixx="0.003" ixy="0" ixz="0" iyy="0.0030" iyz="0" izz="0.0035"/>
    </inertial>
    <visual>
      <origin xyz="0 0 0" rpy="0 0 0" />
      <geometry>
        <mesh  filename="package://human_arm_description/meshes/wristx.stl" />
      </geometry>
      <material name="">
        <color rgba="0.79216 0.81961 0.93333 1" />
      </material>
    </visual>
    <collision>
      <origin xyz="0 0 0" rpy="0 0 0" />
      <geometry>
          <mesh  filename="package://human_arm_description/meshes/wristx.stl" />
      </geometry>
    </collision>
</link>








<joint
    name="${prefix}wristx_wristz" type="revolute">
    <origin xyz="0.000 -0.035 0.000" rpy="0 0 0" />
    <parent link="${prefix}wristx" />
    <child link="${prefix}wristz" />
    <axis xyz="1 0 0" />
    <limit lower="-1" upper="1.57" effort="150.0" velocity="1"/>
    <!-- dynamics damping="5" friction="0.0"/ -->
</joint>



<link name="${prefix}wristz">
    <inertial>
      <origin xyz="0 0 0" rpy="0 0 0" />
      <mass value="0.7" />
          <inertia ixx="0.003" ixy="0" ixz="0" iyy="0.0030" iyz="0" izz="0.0035"/>
    </inertial>
    <visual>
      <origin xyz="0 0 0" rpy="0 0 0" />
      <geometry>
        <mesh  filename="package://human_arm_description/meshes/wristz.stl" />
      </geometry>
      <material name="">
        <color rgba="0.79216 0.81961 0.93333 1" />
      </material>
    </visual>
    <collision>
      <origin xyz="0 0 0" rpy="0 0 0" />
      <geometry>
          <mesh  filename="package://human_arm_description/meshes/wristz.stl" />
      </geometry>
    </collision>
</link>



<joint
    name="${prefix}wristz_palm" type="fixed">
    <origin xyz="0.03 -0.02 0.000" rpy="0 0 0" />
    <parent link="${prefix}wristz" />
    <child link="${prefix}palm" />
    <axis xyz="0 0 1" />
    <limit lower="-0.697" upper="1.57" effort="150.0" velocity="1"/>
    <!-- dynamics damping="5" friction="0.0"/ -->
</joint>



<link name="${prefix}palm">
    <inertial>
      <origin xyz="0 0 0" rpy="0 0 0" />
      <mass value="0.7" />
          <inertia ixx="0.003" ixy="0" ixz="0" iyy="0.0030" iyz="0" izz="0.0035"/>
    </inertial>
    <visual>
      <origin xyz="0 0 0" rpy="0 0 0" />
      <geometry>
        <mesh  filename="package://human_arm_description/meshes/palm.stl" />
      </geometry>
      <material name="">
        <color rgba="0.79216 0.81961 0.93333 1" />
      </material>
    </visual>
    <collision>
      <origin xyz="0 0 0" rpy="0 0 0" />
      <geometry>
          <mesh  filename="package://human_arm_description/meshes/palm.stl" />
      </geometry>
    </collision>
</link>











<!-- ############################################################################
############################################################################
##################### INDEX FINGER ######################################## -->



<joint
    name="${prefix}palm_index0" type="revolute">
    <origin xyz="0.010 -0.060 0.000" rpy="0 0 0" />
    <parent link="${prefix}palm" />
    <child link="${prefix}index0" />
    <axis xyz="0 0 1" />
    <limit lower="-0.3" upper="0.3" effort="150.0" velocity="1"/>
    <!-- dynamics damping="5" friction="0.0"/ -->
</joint>








<link name="${prefix}index0">
    <inertial>
      <origin xyz="0 0 0" rpy="0 0 0" />
      <mass value="0.7" />
          <inertia ixx="0.003" ixy="0" ixz="0" iyy="0.0030" iyz="0" izz="0.0035"/>
    </inertial>
    <visual>
      <origin xyz="0 0 0" rpy="0 0 0" />
      <geometry>
        <mesh  filename="package://human_arm_description/meshes/index0.stl" />
      </geometry>
      <material name="">
        <color rgba="0.79216 0.81961 0.93333 1" />
      </material>
    </visual>
    <collision>
      <origin xyz="0 0 0" rpy="0 0 0" />
      <geometry>
          <mesh  filename="package://human_arm_description/meshes/index0.stl" />
      </geometry>
    </collision>
</link>





<joint
    name="${prefix}index0_index1" type="revolute">
    <origin xyz="0.00 -0.015 0.000" rpy="0 0 0" />
    <parent link="${prefix}index0" />
    <child link="${prefix}index1" />
    <axis xyz="1 0 0" />
    <limit lower="-0.2" upper="1.57" effort="150.0" velocity="1"/>
    <!-- dynamics damping="5" friction="0.0"/ -->
</joint>



<link name="${prefix}index1">
    <inertial>
      <origin xyz="0 0 0" rpy="0 0 0" />
      <mass value="0.7" />
          <inertia ixx="0.003" ixy="0" ixz="0" iyy="0.0030" iyz="0" izz="0.0035"/>
    </inertial>
    <visual>
      <origin xyz="0 0 0" rpy="0 0 0" />
      <geometry>
        <mesh  filename="package://human_arm_description/meshes/index1.stl" />
      </geometry>
      <material name="">
        <color rgba="0.79216 0.81961 0.93333 1" />
      </material>
    </visual>
    <collision>
      <origin xyz="0 0 0" rpy="0 0 0" />
      <geometry>
          <mesh  filename="package://human_arm_description/meshes/index1.stl" />
      </geometry>
    </collision>
</link>




<joint
    name="${prefix}index1_index2" type="revolute">
    <origin xyz="0.001 -0.040 0.000" rpy="0 0 0" />
    <parent link="${prefix}index1" />
    <child link="${prefix}index2" />
    <axis xyz="1 0 0" />
    <limit lower="0" upper="1.57" effort="150.0" velocity="1"/>
    <!-- dynamics damping="5" friction="0.0"/ -->
</joint>



<link name="${prefix}index2">
    <inertial>
      <origin xyz="0 0 0" rpy="0 0 0" />
      <mass value="0.7" />
          <inertia ixx="0.003" ixy="0" ixz="0" iyy="0.0030" iyz="0" izz="0.0035"/>
    </inertial>
    <visual>
      <origin xyz="0 0 0" rpy="0 0 0" />
      <geometry>
        <mesh  filename="package://human_arm_description/meshes/index2.stl" scale="1 0.8 1" />
      </geometry>
      <material name="">
        <color rgba="0.79216 0.81961 0.93333 1" />
      </material>
    </visual>
    <collision>
      <origin xyz="0 0 0" rpy="0 0 0" />
      <geometry>
          <mesh  filename="package://human_arm_description/meshes/index2.stl" scale="1 0.8 1" />
      </geometry>
    </collision>
</link>






<joint
    name="${prefix}index2_index3" type="revolute">
    <origin xyz="0.00 -0.017 0.000" rpy="0 0 0" />
    <parent link="${prefix}index2" />
    <child link="${prefix}index3" />
    <axis xyz="1 0 0" />
    <limit lower="0" upper="1.57" effort="150.0" velocity="1"/>
    <!-- dynamics damping="5" friction="0.0"/ -->
</joint>



<link name="${prefix}index3">
    <inertial>
      <origin xyz="0 0 0" rpy="0 0 0" />
      <mass value="0.7" />
          <inertia ixx="0.003" ixy="0" ixz="0" iyy="0.0030" iyz="0" izz="0.0035"/>
    </inertial>
    <visual>
      <origin xyz="0 0 0" rpy="0 0 0" />
      <geometry>
        <mesh  filename="package://human_arm_description/meshes/index3.stl" />
      </geometry>
      <material name="">
        <color rgba="0.79216 0.81961 0.93333 1" />
      </material>
    </visual>
    <collision>
      <origin xyz="0 0 0" rpy="0 0 0" />
      <geometry>
          <mesh  filename="package://human_arm_description/meshes/index3.stl" />
      </geometry>
    </collision>
</link>










<!-- ############################################################################
############################################################################
##################### MIDDLE FINGER ######################################## -->



<joint
    name="${prefix}palm_middle0" type="revolute">
    <origin xyz="-0.011 -0.07 0.000" rpy="0 0 0" />
    <parent link="${prefix}palm" />
    <child link="${prefix}middle0" />
    <axis xyz="0 0 1" />
    <limit lower="-0.3" upper="0.3" effort="150.0" velocity="1"/>
    <!-- dynamics damping="5" friction="0.0"/ -->
</joint>



<link name="${prefix}middle0">
    <inertial>
      <origin xyz="0 0 0" rpy="0 0 0" />
      <mass value="0.7" />
          <inertia ixx="0.003" ixy="0" ixz="0" iyy="0.0030" iyz="0" izz="0.0035"/>
    </inertial>
    <visual>
      <origin xyz="0 0 0" rpy="0 0 0" />
      <geometry>
        <mesh  filename="package://human_arm_description/meshes/middle0.stl" />
      </geometry>
      <material name="">
        <color rgba="0.79216 0.81961 0.93333 1" />
      </material>
    </visual>
    <collision>
      <origin xyz="0 0 0" rpy="0 0 0" />
      <geometry>
          <mesh  filename="package://human_arm_description/meshes/middle0.stl" />
      </geometry>
    </collision>
</link>





<joint
    name="${prefix}middle0_middle1" type="revolute">
    <origin xyz="0.00 -0.020 0.000" rpy="0 0 0" />
    <parent link="${prefix}middle0" />
    <child link="${prefix}middle1" />
    <axis xyz="1 0 0" />
    <limit lower="-0.2" upper="1.57" effort="150.0" velocity="1"/>
    <!-- dynamics damping="5" friction="0.0"/ -->
</joint>



<link name="${prefix}middle1">
    <inertial>
      <origin xyz="0 0 0" rpy="0 0 0" />
      <mass value="0.7" />
          <inertia ixx="0.003" ixy="0" ixz="0" iyy="0.0030" iyz="0" izz="0.0035"/>
    </inertial>
    <visual>
      <origin xyz="0 0 0" rpy="0 0 0" />
      <geometry>
        <mesh  filename="package://human_arm_description/meshes/middle1.stl" />
      </geometry>
      <material name="">
        <color rgba="0.79216 0.81961 0.93333 1" />
      </material>
    </visual>
    <collision>
      <origin xyz="0 0 0" rpy="0 0 0" />
      <geometry>
          <mesh  filename="package://human_arm_description/meshes/middle1.stl" />
      </geometry>
    </collision>
</link>




<joint
    name="${prefix}middle1_middle2" type="revolute">
    <origin xyz="0.001 -0.045 0.000" rpy="0 0 0" />
    <parent link="${prefix}middle1" />
    <child link="${prefix}middle2" />
    <axis xyz="1 0 0" />
    <limit lower="0" upper="1.57" effort="150.0" velocity="1"/>
    <!-- dynamics damping="5" friction="0.0"/ -->
</joint>



<link name="${prefix}middle2">
    <inertial>
      <origin xyz="0 0 0" rpy="0 0 0" />
      <mass value="0.7" />
          <inertia ixx="0.003" ixy="0" ixz="0" iyy="0.0030" iyz="0" izz="0.0035"/>
    </inertial>
    <visual>
      <origin xyz="0 0 0" rpy="0 0 0" />
      <geometry>
        <mesh  filename="package://human_arm_description/meshes/middle2.stl" scale="1 0.9 1"/>
      </geometry>
      <material name="">
        <color rgba="0.79216 0.81961 0.93333 1" />
      </material>
    </visual>
    <collision>
      <origin xyz="0 0 0" rpy="0 0 0" />
      <geometry>
          <mesh  filename="package://human_arm_description/meshes/middle2.stl" scale="1 0.9 1"/>
      </geometry>
    </collision>
</link>






<joint
    name="${prefix}middle2_middle3" type="revolute">
    <origin xyz="0.00 -0.023 0.000" rpy="0 0 0" />
    <parent link="${prefix}middle2" />
    <child link="${prefix}middle3" />
    <axis xyz="1 0 0" />
    <limit lower="0" upper="1.57" effort="150.0" velocity="1"/>
    <!-- dynamics damping="5" friction="0.0"/ -->
</joint>



<link name="${prefix}middle3">
    <inertial>
      <origin xyz="0 0 0" rpy="0 0 0" />
      <mass value="0.7" />
          <inertia ixx="0.003" ixy="0" ixz="0" iyy="0.0030" iyz="0" izz="0.0035"/>
    </inertial>
    <visual>
      <origin xyz="0 0 0" rpy="0 0 0" />
      <geometry>
        <mesh  filename="package://human_arm_description/meshes/middle3.stl" />
      </geometry>
      <material name="">
        <color rgba="0.79216 0.81961 0.93333 1" />
      </material>
    </visual>
    <collision>
      <origin xyz="0 0 0" rpy="0 0 0" />
      <geometry>
          <mesh  filename="package://human_arm_description/meshes/middle3.stl" />
      </geometry>
    </collision>
</link>






<!-- ############################################################################
############################################################################
##################### RING FINGER ######################################## -->












<joint
    name="${prefix}palm_ring0" type="revolute">
    <origin xyz="-0.034 -0.065 0.000" rpy="0 0 0" />
    <parent link="${prefix}palm" />
    <child link="${prefix}ring0" />
    <axis xyz="0 0 1" />
    <limit lower="-0.3" upper="0.3" effort="150.0" velocity="1"/>
    <!-- dynamics damping="5" friction="0.0"/ -->
</joint>



<link name="${prefix}ring0">
    <inertial>
      <origin xyz="0 0 0" rpy="0 0 0" />
      <mass value="0.7" />
          <inertia ixx="0.003" ixy="0" ixz="0" iyy="0.0030" iyz="0" izz="0.0035"/>
    </inertial>
    <visual>
      <origin xyz="0 0 0" rpy="0 0 0" />
      <geometry>
        <mesh  filename="package://human_arm_description/meshes/ring0.stl" />
      </geometry>
      <material name="">
        <color rgba="0.79216 0.81961 0.93333 1" />
      </material>
    </visual>
    <collision>
      <origin xyz="0 0 0" rpy="0 0 0" />
      <geometry>
          <mesh  filename="package://human_arm_description/meshes/ring0.stl" />
      </geometry>
    </collision>
</link>




<joint
    name="${prefix}ring0_ring1" type="revolute">
    <origin xyz="0.00 -0.020 0.000" rpy="0 0 0" />
    <parent link="${prefix}ring0" />
    <child link="${prefix}ring1" />
    <axis xyz="1 0 0" />
    <limit lower="-0.2" upper="1.57" effort="150.0" velocity="1"/>
    <!-- dynamics damping="5" friction="0.0"/ -->
</joint>



<link name="${prefix}ring1">
    <inertial>
      <origin xyz="0 0 0" rpy="0 0 0" />
      <mass value="0.7" />
          <inertia ixx="0.003" ixy="0" ixz="0" iyy="0.0030" iyz="0" izz="0.0035"/>
    </inertial>
    <visual>
      <origin xyz="0 0 0" rpy="0 0 0" />
      <geometry>
        <mesh  filename="package://human_arm_description/meshes/ring1.stl" />
      </geometry>
      <material name="">
        <color rgba="0.79216 0.81961 0.93333 1" />
      </material>
    </visual>
    <collision>
      <origin xyz="0 0 0" rpy="0 0 0" />
      <geometry>
          <mesh  filename="package://human_arm_description/meshes/ring1.stl" />
      </geometry>
    </collision>
</link>







<joint
    name="${prefix}ring1_ring2" type="revolute">
    <origin xyz="0.001 -0.041 0.000" rpy="0 0 0" />
    <parent link="${prefix}ring1" />
    <child link="${prefix}ring2" />
    <axis xyz="1 0 0" />
    <limit lower="0" upper="1.57" effort="150.0" velocity="1"/>
    <!-- dynamics damping="5" friction="0.0"/ -->
</joint>



<link name="${prefix}ring2">
    <inertial>
      <origin xyz="0 0 0" rpy="0 0 0" />
      <mass value="0.7" />
          <inertia ixx="0.003" ixy="0" ixz="0" iyy="0.0030" iyz="0" izz="0.0035"/>
    </inertial>
    <visual>
      <origin xyz="0 0 0" rpy="0 0 0" />
      <geometry>
        <mesh  filename="package://human_arm_description/meshes/ring2.stl" scale="1 0.8 1" />
      </geometry>
      <material name="">
        <color rgba="0.79216 0.81961 0.93333 1" />
      </material>
    </visual>
    <collision>
      <origin xyz="0 0 0" rpy="0 0 0" />
      <geometry>
          <mesh  filename="package://human_arm_description/meshes/ring2.stl" scale="1 0.8 1" />
      </geometry>
    </collision>
</link>






<joint
    name="${prefix}ring2_ring3" type="revolute">
    <origin xyz="0.00 -0.019 0.000" rpy="0 0 0" />
    <parent link="${prefix}ring2" />
    <child link="${prefix}ring3" />
    <axis xyz="1 0 0" />
    <limit lower="0" upper="1.57" effort="150.0" velocity="1"/>
    <!-- dynamics damping="5" friction="0.0"/ -->
</joint>



<link name="${prefix}ring3">
    <inertial>
      <origin xyz="0 0 0" rpy="0 0 0" />
      <mass value="0.7" />
          <inertia ixx="0.003" ixy="0" ixz="0" iyy="0.0030" iyz="0" izz="0.0035"/>
    </inertial>
    <visual>
      <origin xyz="0 0 0" rpy="0 0 0" />
      <geometry>
        <mesh  filename="package://human_arm_description/meshes/ring3.stl" />
      </geometry>
      <material name="">
        <color rgba="0.79216 0.81961 0.93333 1" />
      </material>
    </visual>
    <collision>
      <origin xyz="0 0 0" rpy="0 0 0" />
      <geometry>
          <mesh  filename="package://human_arm_description/meshes/ring3.stl" />
      </geometry>
    </collision>
</link>






<!-- ############################################################################
############################################################################
##################### PINKY FINGER ######################################## -->






<joint
    name="${prefix}palm_pinky0" type="revolute">
    <origin xyz="-0.056 -0.05 0.000" rpy="0 0 0" />
    <parent link="${prefix}palm" />
    <child link="${prefix}pinky0" />
    <axis xyz="0 0 1" />
    <limit lower="-0.3" upper="0.3" effort="150.0" velocity="1"/>
    <!-- dynamics damping="5" friction="0.0"/ -->
</joint>



<link name="${prefix}pinky0">
    <inertial>
      <origin xyz="0 0 0" rpy="0 0 0" />
      <mass value="0.7" />
          <inertia ixx="0.003" ixy="0" ixz="0" iyy="0.0030" iyz="0" izz="0.0035"/>
    </inertial>
    <visual>
      <origin xyz="0 0 0" rpy="0 0 0" />
      <geometry>
        <mesh  filename="package://human_arm_description/meshes/pinky0.stl" />
      </geometry>
      <material name="">
        <color rgba="0.79216 0.81961 0.93333 1" />
      </material>
    </visual>
    <collision>
      <origin xyz="0 0 0" rpy="0 0 0" />
      <geometry>
          <mesh  filename="package://human_arm_description/meshes/pinky0.stl" />
      </geometry>
    </collision>
</link>







<joint
    name="${prefix}pinky0_pinky1" type="revolute">
    <origin xyz="0.00 -0.020 0.000" rpy="0 0 0" />
    <parent link="${prefix}pinky0" />
    <child link="${prefix}pinky1" />
    <axis xyz="1 0 0" />
    <limit lower="-0.2" upper="1.57" effort="150.0" velocity="1"/>
    <!-- dynamics damping="5" friction="0.0"/ -->
</joint>



<link name="${prefix}pinky1">
    <inertial>
      <origin xyz="0 0 0" rpy="0 0 0" />
      <mass value="0.7" />
          <inertia ixx="0.003" ixy="0" ixz="0" iyy="0.0030" iyz="0" izz="0.0035"/>
    </inertial>
    <visual>
      <origin xyz="0 0 0" rpy="0 0 0" />
      <geometry>
        <mesh  filename="package://human_arm_description/meshes/pinky1.stl" />
      </geometry>
      <material name="">
        <color rgba="0.79216 0.81961 0.93333 1" />
      </material>
    </visual>
    <collision>
      <origin xyz="0 0 0" rpy="0 0 0" />
      <geometry>
          <mesh  filename="package://human_arm_description/meshes/pinky1.stl" />
      </geometry>
    </collision>
</link>







<joint
    name="${prefix}pinky1_pinky2" type="revolute">
    <origin xyz="0.001 -0.041 0.000" rpy="0 0 0" />
    <parent link="${prefix}pinky1" />
    <child link="${prefix}pinky2" />
    <axis xyz="1 0 0" />
    <limit lower="0" upper="1.57" effort="150.0" velocity="1"/>
    <!-- dynamics damping="5" friction="0.0"/ -->
</joint>



<link name="${prefix}pinky2">
    <inertial>
      <origin xyz="0 0 0" rpy="0 0 0" />
      <mass value="0.7" />
          <inertia ixx="0.003" ixy="0" ixz="0" iyy="0.0030" iyz="0" izz="0.0035"/>
    </inertial>
    <visual>
      <origin xyz="0 0 0" rpy="0 0 0" />
      <geometry>
        <mesh  filename="package://human_arm_description/meshes/pinky2.stl" />
      </geometry>
      <material name="">
        <color rgba="0.79216 0.81961 0.93333 1" />
      </material>
    </visual>
    <collision>
      <origin xyz="0 0 0" rpy="0 0 0" />
      <geometry>
          <mesh  filename="package://human_arm_description/meshes/pinky2.stl" />
      </geometry>
    </collision>
</link>






<joint
    name="${prefix}pinky2_pinky3" type="revolute">
    <origin xyz="0.00 -0.019 0.000" rpy="0 0 0" />
    <parent link="${prefix}pinky2" />
    <child link="${prefix}pinky3" />
    <axis xyz="1 0 0" />
    <limit lower="0" upper="1.57" effort="150.0" velocity="1"/>
    <!-- dynamics damping="5" friction="0.0"/ -->
</joint>



<link name="${prefix}pinky3">
    <inertial>
      <origin xyz="0 0 0" rpy="0 0 0" />
      <mass value="0.7" />
          <inertia ixx="0.003" ixy="0" ixz="0" iyy="0.0030" iyz="0" izz="0.0035"/>
    </inertial>
    <visual>
      <origin xyz="0 0 0" rpy="0 0 0" />
      <geometry>
        <mesh  filename="package://human_arm_description/meshes/pinky3.stl" />
      </geometry>
      <material name="">
        <color rgba="0.79216 0.81961 0.93333 1" />
      </material>
    </visual>
    <collision>
      <origin xyz="0 0 0" rpy="0 0 0" />
      <geometry>
          <mesh  filename="package://human_arm_description/meshes/pinky3.stl" />
      </geometry>
    </collision>
</link>







<!-- ############################################################################
############################################################################
##################### Thumb FINGER ######################################## -->


<joint
    name="${prefix}palm_thumb_zero" type="revolute">
    <origin xyz="-0.005 -0.02 0.000" rpy="0 0 0" />
    <parent link="${prefix}palm" />
    <child link="${prefix}thumb_zero_zero" />
    <axis xyz="1 0 0" />
    <limit lower="0" upper="1.8" effort="150.0" velocity="1"/>
    <!-- dynamics damping="5" friction="0.0"/ -->
</joint>

<link name="${prefix}thumb_zero_zero">

    <inertial>
      <origin xyz="0 0 0" rpy="0 0 0" />
      <mass value="0.7" />
          <inertia ixx="0.003" ixy="0" ixz="0" iyy="0.0030" iyz="0" izz="0.0035"/>
    </inertial>
    <visual>
      <origin xyz="0 0 0" rpy="0 0 0" />
      <geometry>
        <cylinder length="0.005" radius="0.01"/>
      </geometry>
      <material name="">
        <color rgba="0.79216 0.81961 0.93333 1" />
      </material>
    </visual>
    <collision>
      <origin xyz="0 0 0" rpy="0 0 0" />
      <geometry>
         <cylinder length="0.005" radius="0.01"/>
      </geometry>
    </collision>

</link>





<joint
    name="${prefix}palm_thumb0" type="revolute">
    <origin xyz="0.00 -0.0 0.000" rpy="0 0 0" />
    <parent link="${prefix}thumb_zero_zero" />
    <child link="${prefix}thumb0" />
    <axis xyz="0 1 0" />
    <limit lower="0" upper="1.8" effort="150.0" velocity="1"/>
    <!-- dynamics damping="5" friction="0.0"/ -->
</joint>



<link name="${prefix}thumb0">
    <inertial>
      <origin xyz="0 0 0" rpy="0 0 0" />
      <mass value="0.7" />
          <inertia ixx="0.003" ixy="0" ixz="0" iyy="0.0030" iyz="0" izz="0.0035"/>
    </inertial>
    <visual>
      <origin xyz="0 0 0" rpy="0 0 0" />
      <geometry>
        <mesh  filename="package://human_arm_description/meshes/thumb0.stl" />
      </geometry>
      <material name="">
        <color rgba="0.79216 0.81961 0.93333 1" />
      </material>
    </visual>
    <collision>
      <origin xyz="0 0 0" rpy="0 0 0" />
      <geometry>
          <mesh  filename="package://human_arm_description/meshes/thumb0.stl" />
      </geometry>
    </collision>
</link>







<joint
    name="${prefix}thumb0_thumb1" type="revolute">
    <origin xyz="0.02 0 0.000" rpy="0 0 0" />
    <parent link="${prefix}thumb0" />
    <child link="${prefix}thumb1" />
    <axis xyz="0 0 1" />
    <limit lower="-1" upper="0" effort="150.0" velocity="1"/>
    <!-- dynamics damping="5" friction="0.0"/ -->
</joint>



<link name="${prefix}thumb1">
    <inertial>
      <origin xyz="0 0 0" rpy="0 0 0" />
      <mass value="0.7" />
          <inertia ixx="0.003" ixy="0" ixz="0" iyy="0.0030" iyz="0" izz="0.0035"/>
    </inertial>
    <visual>
      <origin xyz="0 0 0" rpy="0 0 0" />
      <geometry>
        <mesh  filename="package://human_arm_description/meshes/thumb1.stl" scale="0.6 1 1" />
      </geometry>
      <material name="">
        <color rgba="0.79216 0.81961 0.93333 1" />
      </material>
    </visual>
    <collision>
      <origin xyz="0 0 0" rpy="0 0 0" />
      <geometry>
          <mesh  filename="package://human_arm_description/meshes/thumb1.stl" scale="0.6 1 1" />
      </geometry>
    </collision>
</link>







<joint
    name="${prefix}thumb1_thumb2" type="revolute">
    <origin xyz="0.018 0 0.000" rpy="0 0 0" />
    <parent link="${prefix}thumb1" />
    <child link="${prefix}thumb2" />
    <axis xyz="0 0 1" />
    <limit lower="-0.8" upper="0" effort="150.0" velocity="1"/>
    <!-- dynamics damping="5" friction="0.0"/ -->
</joint>



<link name="${prefix}thumb2">
    <inertial>
      <origin xyz="0 0 0" rpy="0 0 0" />
      <mass value="0.7" />
          <inertia ixx="0.003" ixy="0" ixz="0" iyy="0.0030" iyz="0" izz="0.0035"/>
    </inertial>
    <visual>
      <origin xyz="0 0 0" rpy="0 0 0" />
      <geometry>
        <mesh  filename="package://human_arm_description/meshes/thumb2.stl" scale="0.6 1 1"/>
      </geometry>
      <material name="">
        <color rgba="0.79216 0.81961 0.93333 1" />
      </material>
    </visual>
    <collision>
      <origin xyz="0 0 0" rpy="0 0 0" />
      <geometry>
          <mesh  filename="package://human_arm_description/meshes/thumb2.stl" scale="0.6 1 1" />
      </geometry>
    </collision>
</link>






<joint
    name="${prefix}thumb2_thumb3" type="revolute">
    <origin xyz="0.02 0 0.000" rpy="0 0 0" />
    <parent link="${prefix}thumb2" />
    <child link="${prefix}thumb3" />
    <axis xyz="0 0 1" />
    <limit lower="-0.697" upper="0" effort="150.0" velocity="1"/>
    <!-- dynamics damping="5" friction="0.0"/ -->
</joint>



<link name="${prefix}thumb3">
    <inertial>
      <origin xyz="0 0 0" rpy="0 0 0" />
      <mass value="0.7" />
          <inertia ixx="0.003" ixy="0" ixz="0" iyy="0.0030" iyz="0" izz="0.0035"/>
    </inertial>
    <visual>
      <origin xyz="0 0 0" rpy="0 0 0" />
      <geometry>
        <mesh  filename="package://human_arm_description/meshes/thumb3.stl" />
      </geometry>
      <material name="">
        <color rgba="0.79216 0.81961 0.93333 1" />
      </material>
    </visual>
    <collision>
      <origin xyz="0 0 0" rpy="0 0 0" />
      <geometry>
          <mesh  filename="package://human_arm_description/meshes/thumb3.stl" />
      </geometry>
    </collision>
</link>














</robot>











